Workbook
Name TOTALD.21: #REF!
Name TOTALD.21: #REF!
Name TOTALOFERTA: #REF!
Name TOTALOFERTA: #REF!
Name TOTALP.1: #REF!
Name TOTALP.1: #REF!
Name TOTALP.2: #REF!
Name TOTALP.2: #REF!
Name TOTALP.3: #REF!
Name TOTALP.3: #REF!
Name TOTALP.31HOG: #REF!
Name TOTALP.31HOG: #REF!
Name TOTALP.5: #REF!
Name TOTALP.5: #REF!
Name TOTALP.51: #REF!
Name TOTALP.51: #REF!
Name TOTALP.52: #REF!
Name TOTALP.52: #REF!
Name TOTALP.6: #REF!
Name TOTALP.6: #REF!
Name TOTALP.7: #REF!
Name TOTALP.7: #REF!
Name TOTALP2EQ: #REF!
Name TOTALP2EQ: #REF!
Name TOTALP31ISFLSH: #REF!
Name TOTALP31ISFLSH: #REF!
Name TOTALP3GOB: #REF!
Name TOTALP3GOB: #REF!
Name TOTALUTILIZ.1: #REF!
Name TOTALUTILIZ.1: #REF!

Sheet Oferta
A1: SISTEMA DE CUENTAS NACIONALES DE PANAMÁ
A2: CUADRO DE OFERTA Y UTILIZACIÓN
A3: OFERTA DE PRODUCTOS A PRECIOS DE COMPRADOR
A4: AÑO: | B4: 2021
A5: (en millones de B/.)
A7: Serie Preliminar
A8: NOMENCLATURA DE PRODUCTOS Y TRANSACCIONES | C8: P. 1 P R O D U C C I Ó N D E L A S I N D U S T R I A S (CLASIFICACIÓN DE ACTIVIDADES ECONÓMICAS - CAP)
C9: P.11 PRODUCCIÓN DE MERCADO | BZ9: P.12 PRODUCCIÓN PARA USO FINAL PROPIO | CD9: P.13 OTRA PRODUCCIÓN NO DE MERCADO | CR9: P.7 IMPORTACIONES CIF | CU9: AJUSTE CIF/FOB SOBRE IMPORTACIONES | CW9: D.21 IMPUESTOS SOBRE PRODUCTOS | DC9: MÁRGENES DE DISTRIBUCIÓN
B10: INDUSTRIAS | C10: 01.1 | D10: 02.1 | E10: 03.1 | F10: 04.1 | G10: 05.1 | H10: 06.1 | I10: 07.1 | J10: 08.1 | K10: 08.2 | L10: 08.3 | M10: 08.4 | N10: 09.1 | O10: 10.1 | P10: 11.1 | Q10: 12.1 | R10: 13.1 | S10: 14.1 | T10: 15.1 | U10: 16.1 | V10: 17.1 | W10: 18.1 | X10: 19.1 | Y10: 19.2 | Z10: 20.1 | AA10: 21.1 | AB10: 22.1 | AC10: 23.1 | AD10: 24.1 | AE10: 25.1 | AF10: 26.1 | AG10: 27.1 | AH10: 28.1 | AI10: 29.1 | AJ10: 30.1 | AK10: 31.1 | AL10: 31.2 | AM10: 32.1 | AN10: 33.1 | AO10: 34.1 | AP10: 35.1 | AQ10: 35.2 M | AR10: 36.1 M | AS10: 37.1 | AT10: 38.1 | AU10: 38.2 | AV10: 38.3 | AW10: 39.1 | AX10: 39.2 | AY10: 39.3 | AZ10: 39.4 | BA10: 39.5 | BB10: 39.6 | BC10: 39.7 | BD10: 39.8 | BE10: 39.9 | BF10: 40.1 | BG10: 40.2 | BH10: 41.1 M | BI10: 41.2 | BJ10: 42.1 | BK10: 42.2 | BL10: 42.3 | BM10: 43.1 M | BN10: 43.2 | BO10: 44.1 | BP10: 44.2 | BQ10: 44.3 M | BR10: 44.4 | BS10: 44.5 | BT10: 44.6 M | BU10: 45.1 M | BV10: 46.1 M | BW10: 47.1 M | BX10: 48.1 M | BZ10: 36.1 UFP | CA10: 43.1 UFP | CB10: 49.1 | CD10: 35.2 NM | CE10: 41.1 NM | CF10: 44.3 NM | CG10: 50.1 | CH10: 50.2 | CI10: 50.3 | CJ10: 45.1 NM | CK10: 46.1 NM | CL10: 47.1 NM | CM10: 48.1 NM | CW10: D.211 IMPUESTOS TIPO IVA | CX10: D.212 IMPUESTOS TIPO IVA | CY10: D.213 IMPUESTOS SOBRE LA EXPORTACIÓN | CZ10: D.214 IMP.A LOS PRODUCTOS EXC. IVA, IMP A LA IMPORT.
A11: CÓDIGO | B11: P R O D U C T O S | C11: Cultivo de cereales, legumbres y semillas oleaginosas | D11: Cultivo de maiz | E11: Cultivo de arroz | F11: Cultivo de vegetales, raíces y tubérculos | G11: Cultivo de Banano | H11: Cultivo de otras frutas y nueces | I11: Otras actividades agrícolas | J11: Cría de ganado bovino (excluye búfalo) | K11: Cría de ganado porcino | L11: Cría de aves de corral | M11: Cría de otros animales y obtención de subproductos | N11: Actividades de apoyo agropecuario | O11: Silvicultura, extracción de madera y actividades conexas | P11: Pesca | Q11: Acuicultura | R11: Explotación minas y canteras | S11: Procesamiento y conservación de carne | T11: Procesamiento y conservación de pescado, crustáceos y moluscos | U11: Procesamiento y conservación de frutas y vegetales | V11: Elaboración de aceites y grasas de origen vegetal y animal | W11: Elaboración de productos lácteos | X11: Elaboración de productos de molinería, almidones y productos derivados del almidón | Y11: Elaboración de otros productos alimenticios | Z11: Elaboración de bebidas y tabaco | AA11: Fabricación de productos textiles y prendas de vestir | AB11: Fabricación de cuero, productos conexos y calzado | AC11: Producción de madera y fabricación de productos de madera y corcho, excepto muebles; fabricación de artículos de paja y de materiales trenzables | AD11: Fabricacion de papel y productos de papel | AE11: Actividades de impresión y servicios conexos | AF11: Fabricación de sustancias y productos químicos | AG11: Fabricación de productos farmacéuticos, sustancias químicas medicinales y de productos botánicos | AH11: Fabricación de productos de caucho y plástico | AI11: Fabricación de cemento, cal y yeso | AJ11: Fabricación de otros productos minerales no metálicos | AK11: Fabricación de metales comunes | AL11: Fabricación de productos metalicos elaborados, excepto maquinaria y equipo | AM11: Otras industrias manufactureras | AN11: Reparación, mantenimiento e instalación de maquinaria y equipo comercial e industrial | AO11: Suministro de electricidad, gas, vapor y aire acondicionado | AP11: Captación, tratamiento y distribuciòn de agua | AQ11: Recogida, tratamiento y eliminación de desechos, recuperación de materiales y actividades de descontaminación y otros servicios de eliminación de desechos | AR11: Construcción | AS11: Comercio al por mayor y menor en zona franca | AT11: Comercio al por mayor, en comisión y de vehículos automotores | AU11: Comercio al por menor | AV11: Mantenimiento y reparación de vehículos automotores y bicicletas | AW11: Transporte por vía terrestre; transporte por tuberías | AX11: Transporte por vía acuática | AY11: Transporte por vía aérea | AZ11: Servicio de almacenamiento y depósito | BA11: Actividades de servicio vinculadas al transporte por vía acuática: Autoridad del Canal de Panamá (ACP) | BB11: Otras actividades de servicio vinculado al transporte por vía acuática | BC11: Actividades de servicio vinculado al transporte por vía aérea: aeropuertos | BD11: Otros actividades de apoyo al transporte | BE11: Actividades postales y de mensajería | BF11: Actividades de alojamientos | BG11: Actividades de servicios de comidas y bebidas | BH11: Actividades de información y comunicación excluída telecomunicaciones | BI11: Telecomunicaciones | BJ11: Actividades de servicios financieros, excepto seguros y fondos de pensiones | BK11: Actividades de seguros, reaseguros y fondos de pensiones, excepto los planes de seguridad social de afiliación obligatoria | BL11: Actividades auxiliares de las actividades de servicios financieros | BM11: Alquiler de viviendas | BN11: Alquileres no residenciales y otras actividades inmobiliarias | BO11: Actividades jurídicas y de contabilidad | BP11: Actividades de arquitectura e ingeniería, ensayos y análisis técnicos | BQ11: Investigación científicas y desarrollo | BR11: Publicidad y estudios de mercados | BS11: Otras actividades profesionales, científicas y técnicas | BT11: Actividades de servicio administrativo y de apoyo | BU11: Enseñanza | BV11: Actividades de atención de la salud humana y de asistencia social | BW11: Actividades artísticas, de entretenimiento y recreativas | BX11: Otras actividades de servicio | BY11: P.11 SUBTOTAL PRODUCCION DE MERCADO | BZ11: Construcción | CA11: Alquiler de viviendas | CB11: Actividades de los hogares como empleadores de personal doméstico | CC11: P.12 SUBTOTAL PRODUCCION PARA USO FINAL PROPIO | CD11: Recogida, tratamiento y eliminación de desechos, recuperación de materiales y actividades de descontaminación y otros servicios de eliminación de desechos | CE11: Actividades de información y comunicación excluída telecomunicaciones | CF11: Investigación científicas y desarrollo | CG11: Administración pública y defensa; exceptos planes de seguridad social de afiliación obligatoria | CH11: Prestación de servicios a la comunidad en general | CI11: Actividades de planes de seguridad social de afiliación obligatoria | CJ11: Enseñanza | CK11: Actividades de atención de la salud humana y de asistencia social | CL11: Actividades artísticas, de entretenimiento y recreativas | CM11: Otras actividades de servicio | CN11: P.13 SUBTOTAL OTRA PRODUCCION NO DE MERCADO | CO11: P.1 TOTAL PRODUCCION (precios básicos) | CR11: P.71 BIENES | CS11: P.72 SERVICIOS | CT11: P.7 TOTAL | CV11: TOTAL OFERTA (a precios básicos) | DA11: D.21 TOTAL | DB11: D.31 SUBVENCIO-NES A LOS PRODUCTOS | DC11: MÁRGENES DE COMERCIO | DD11: MÁRGENES DE DISTRIBUCIÓN DE ELECTRICIDAD | DE11: TOTAL | DF11: TOTAL OFERTA (a precios de comprador)
A12: 0101 | B12: TRIGO | C12: 0 | D12: 0 | E12: 0 | F12: 0 | G12: 0 | H12: 0 | I12: 0 | J12: 0 | K12: 0 | L12: 0 | M12: 0 | N12: 0 | O12: 0 | P12: 0 | Q12: 0 | R12: 0 | S12: 0 | T12: 0 | U12: 0 | V12: 0 | W12: 0 | X12: 0 | Y12: 0 | Z12: 0 | AA12: 0 | AB12: 0 | AC12: 0 | AD12: 0 | AE12: 0 | AF12: 0 | AG12: 0 | AH12: 0 | AI12: 0 | AJ12: 0 | AK12: 0 | AL12: 0 | AM12: 0 | AN12: 0 | AO12: 0 | AP12: 0 | AQ12: 0 | AR12: 0 | AS12: 0 | AT12: 0 | AU12: 0 | AV12: 0 | AW12: 0 | AX12: 0 | AY12: 0 | AZ12: 0 | BA12: 0 | BB12: 0 | BC12: 0 | BD12: 0 | BE12: 0 | BF12: 0 | BG12: 0 | BH12: 0 | BI12: 0 | BJ12: 0 | BK12: 0 | BL12: 0 | BM12: 0 | BN12: 0 | BO12: 0 | BP12: 0 | BQ12: 0 | BR12: 0 | BS12: 0 | BT12: 0 | BU12: 0 | BV12: 0 | BW12: 0 | BX12: 0 | BY12: 0 | BZ12: 0 | CA12: 0 | CB12: 0 | CC12: 0 | CD12: 0 | CE12: 0 | CF12: 0 | CG12: 0 | CH12: 0 | CI12: 0 | CJ12: 0 | CK12: 0 | CL12: 0 | CM12: 0 | CN12: 0 | CO12: 0 | CR12: 50.532696 | CS12: 0 | CT12: 50.532696 | CU12: 0 | CV12: 50.532696 | CW12: 0 | CX12: 0 | CY12: 0 | CZ12: 0 | DA12: 0 | DB12: 0 | DC12: 0 | DD12: 0 | DE12: 0 | DF12: 50.532696
A13: 0102 | B13: OTROS CEREALES (EXCL. MAÍZ Y ARROZ) | C13: 2.1587049 | D13: 0 | E13: 0 | F13: 0 | G13: 0 | H13: 0 | I13: 0 | J13: 0 | K13: 0 | L13: 0 | M13: 0 | N13: 0 | O13: 0 | P13: 0 | Q13: 0 | R13: 0 | S13: 0 | T13: 0 | U13: 0 | V13: 0 | W13: 0 | X13: 0 | Y13: 0 | Z13: 0 | AA13: 0 | AB13: 0 | AC13: 0 | AD13: 0 | AE13: 0 | AF13: 0 | AG13: 0 | AH13: 0 | AI13: 0 | AJ13: 0 | AK13: 0 | AL13: 0 | AM13: 0 | AN13: 0 | AO13: 0 | AP13: 0 | AQ13: 0 | AR13: 0 | AS13: 0 | AT13: 0 | AU13: 0 | AV13: 0 | AW13: 0 | AX13: 0 | AY13: 0 | AZ13: 0 | BA13: 0 | BB13: 0 | BC13: 0 | BD13: 0 | BE13: 0 | BF13: 0 | BG13: 0 | BH13: 0 | BI13: 0 | BJ13: 0 | BK13: 0 | BL13: 0 | BM13: 0 | BN13: 0 | BO13: 0 | BP13: 0 | BQ13: 0 | BR13: 0 | BS13: 0 | BT13: 0 | BU13: 0 | BV13: 0 | BW13: 0 | BX13: 0 | BY13: 2.1587049 | BZ13: 0 | CA13: 0 | CB13: 0 | CC13: 0 | CD13: 0 | CE13: 0 | CF13: 0 | CG13: 0 | CH13: 0 | CI13: 0 | CJ13: 0 | CK13: 0 | CL13: 0 | CM13: 0 | CN13: 0 | CO13: 2.1587049 | CR13: 1.070601 | CS13: 0 | CT13: 1.070601 | CU13: 0 | CV13: 3.2293059 | CW13: 0 | CX13: 0.021152297 | CY13: 0 | CZ13: 0 | DA13: 0.021152297 | DB13: 0 | DC13: 0.0021985264 | DD13: 0 | DE13: 0.0021985264 | DF13: 3.2526567
A14: 0103 | B14: LEGUMBRES | C14: 15.805846 | D14: 0 | E14: 0 | F14: 0 | G14: 0 | H14: 0 | I14: 0 | J14: 0 | K14: 0 | L14: 0 | M14: 0 | N14: 0 | O14: 0 | P14: 0 | Q14: 0 | R14: 0 | S14: 0 | T14: 0 | U14: 0 | V14: 0 | W14: 0 | X14: 0 | Y14: 0 | Z14: 0 | AA14: 0 | AB14: 0 | AC14: 0 | AD14: 0 | AE14: 0 | AF14: 0 | AG14: 0 | AH14: 0 | AI14: 0 | AJ14: 0 | AK14: 0 | AL14: 0 | AM14: 0 | AN14: 0 | AO14: 0 | AP14: 0 | AQ14: 0 | AR14: 0 | AS14: 0 | AT14: 0 | AU14: 0 | AV14: 0 | AW14: 0 | AX14: 0 | AY14: 0 | AZ14: 0 | BA14: 0 | BB14: 0 | BC14: 0 | BD14: 0 | BE14: 0 | BF14: 0 | BG14: 0 | BH14: 0 | BI14: 0 | BJ14: 0 | BK14: 0 | BL14: 0 | BM14: 0 | BN14: 0 | BO14: 0 | BP14: 0 | BQ14: 0 | BR14: 0 | BS14: 0 | BT14: 0 | BU14: 0 | BV14: 0 | BW14: 0 | BX14: 0 | BY14: 15.805846 | BZ14: 0 | CA14: 0 | CB14: 0 | CC14: 0 | CD14: 0 | CE14: 0 | CF14: 0 | CG14: 0 | CH14: 0 | CI14: 0 | CJ14: 0 | CK14: 0 | CL14: 0 | CM14: 0 | CN14: 0 | CO14: 15.805846 | CR14: 17.953794 | CS14: 0 | CT14: 17.953794 | CU14: 0 | CV14: 33.75964 | CW14: 0 | CX14: 1.5760088 | CY14: 0 | CZ14: 0 | DA14: 1.5760088 | DB14: 0 | DC14: 24.180118 | DD14: 0 | DE14: 24.180118 | DF14: 59.515767
A15: 0104 | B15: SEMILLAS OLEAGINOSAS | C15: 0 | D15: 0 | E15: 0 | F15: 0 | G15: 0 | H15: 0 | I15: 0 | J15: 0 | K15: 0 | L15: 0 | M15: 0 | N15: 0 | O15: 0 | P15: 0 | Q15: 0 | R15: 0 | S15: 0 | T15: 0 | U15: 0 | V15: 0 | W15: 0 | X15: 0 | Y15: 0 | Z15: 0 | AA15: 0 | AB15: 0 | AC15: 0 | AD15: 0 | AE15: 0 | AF15: 0 | AG15: 0 | AH15: 0 | AI15: 0 | AJ15: 0 | AK15: 0 | AL15: 0 | AM15: 0 | AN15: 0 | AO15: 0 | AP15: 0 | AQ15: 0 | AR15: 0 | AS15: 0 | AT15: 0 | AU15: 0 | AV15: 0 | AW15: 0 | AX15: 0 | AY15: 0 | AZ15: 0 | BA15: 0 | BB15: 0 | BC15: 0 | BD15: 0 | BE15: 0 | BF15: 0 | BG15: 0 | BH15: 0 | BI15: 0 | BJ15: 0 | BK15: 0 | BL15: 0 | BM15: 0 | BN15: 0 | BO15: 0 | BP15: 0 | BQ15: 0 | BR15: 0 | BS15: 0 | BT15: 0 | BU15: 0 | BV15: 0 | BW15: 0 | BX15: 0 | BY15: 0 | BZ15: 0 | CA15: 0 | CB15: 0 | CC15: 0 | CD15: 0 | CE15: 0 | CF15: 0 | CG15: 0 | CH15: 0 | CI15: 0 | CJ15: 0 | CK15: 0 | CL15: 0 | CM15: 0 | CN15: 0 | CO15: 0 | CR15: 21.164859 | CS15: 0 | CT15: 21.164859 | CU15: 0 | CV15: 21.164859 | CW15: 0 | CX15: 0.12521213 | CY15: 0 | CZ15: 0 | DA15: 0.12521213 | DB15: 0 | DC15: 3.2721537 | DD15: 0 | DE15: 3.2721537 | DF15: 24.562225
A16: 0201 | B16: MAÍZ | C16: 0 | D16: 113.34635 | E16: 0 | F16: 0 | G16: 0 | H16: 0 | I16: 0 | J16: 0 | K16: 0 | L16: 0 | M16: 0 | N16: 0 | O16: 0 | P16: 0 | Q16: 0 | R16: 0 | S16: 0 | T16: 0 | U16: 0 | V16: 0 | W16: 0 | X16: 0 | Y16: 0 | Z16: 0 | AA16: 0 | AB16: 0 | AC16: 0 | AD16: 0 | AE16: 0 | AF16: 0 | AG16: 0 | AH16: 0 | AI16: 0 | AJ16: 0 | AK16: 0 | AL16: 0 | AM16: 0 | AN16: 0 | AO16: 0 | AP16: 0 | AQ16: 0 | AR16: 0 | AS16: 0 | AT16: 0 | AU16: 0 | AV16: 0 | AW16: 0 | AX16: 0 | AY16: 0 | AZ16: 0 | BA16: 0 | BB16: 0 | BC16: 0 | BD16: 0 | BE16: 0 | BF16: 0 | BG16: 0 | BH16: 0 | BI16: 0 | BJ16: 0 | BK16: 0 | BL16: 0 | BM16: 0 | BN16: 0 | BO16: 0 | BP16: 0 | BQ16: 0 | BR16: 0 | BS16: 0 | BT16: 0 | BU16: 0 | BV16: 0 | BW16: 0 | BX16: 0 | BY16: 113.34635 | BZ16: 0 | CA16: 0 | CB16: 0 | CC16: 0 | CD16: 0 | CE16: 0 | CF16: 0 | CG16: 0 | CH16: 0 | CI16: 0 | CJ16: 0 | CK16: 0 | CL16: 0 | CM16: 0 | CN16: 0 | CO16: 113.34635 | CR16: 178.5708 | CS16: 0 | CT16: 178.5708 | CU16: 0 | CV16: 291.91716 | CW16: 0 | CX16: 0.0035876794 | CY16: 0 | CZ16: 0 | DA16: 0.0035876794 | DB16: 0 | DC16: 9.676064 | DD16: 0 | DE16: 9.676064 | DF16: 301.59681
A17: 0301 | B17: ARROZ | C17: 0 | D17: 0 | E17: 148.0428 | F17: 0 | G17: 0 | H17: 0 | I17: 0 | J17: 0 | K17: 0 | L17: 0 | M17: 0 | N17: 0 | O17: 0 | P17: 0 | Q17: 0 | R17: 0 | S17: 0 | T17: 0 | U17: 0 | V17: 0 | W17: 0 | X17: 0 | Y17: 0 | Z17: 0 | AA17: 0 | AB17: 0 | AC17: 0 | AD17: 0 | AE17: 0 | AF17: 0 | AG17: 0 | AH17: 0 | AI17: 0 | AJ17: 0 | AK17: 0 | AL17: 0 | AM17: 0 | AN17: 0 | AO17: 0 | AP17: 0 | AQ17: 0 | AR17: 0 | AS17: 0 | AT17: 0 | AU17: 0 | AV17: 0 | AW17: 0 | AX17: 0 | AY17: 0 | AZ17: 0 | BA17: 0 | BB17: 0 | BC17: 0 | BD17: 0 | BE17: 0 | BF17: 0 | BG17: 0 | BH17: 0 | BI17: 0 | BJ17: 0 | BK17: 0 | BL17: 0 | BM17: 0 | BN17: 0 | BO17: 0 | BP17: 0 | BQ17: 0 | BR17: 0 | BS17: 0 | BT17: 0 | BU17: 0 | BV17: 0 | BW17: 0 | BX17: 0 | BY17: 148.0428 | BZ17: 0 | CA17: 0 | CB17: 0 | CC17: 0 | CD17: 0 | CE17: 0 | CF17: 0 | CG17: 0.08363696 | CH17: 0 | CI17: 0 | CJ17: 0 | CK17: 0 | CL17: 0 | CM17: 0 | CN17: 0.08363696 | CO17: 148.12643 | CR17: 9.211963 | CS17: 0 | CT17: 9.211963 | CU17: 0 | CV17: 157.3384 | CW17: 0 | CX17: 1.4255137 | CY17: 0 | CZ17: 0 | DA17: 1.4255137 | DB17: 0 | DC17: 7.9346115 | DD17: 0 | DE17: 7.9346115 | DF17: 166.69852
A18: 0401 | B18: HORTALIZAS DE HOJA O DE TALLO | C18: 0 | D18: 0 | E18: 0 | F18: 13.249195 | G18: 0 | H18: 0 | I18: 0 | J18: 0 | K18: 0 | L18: 0 | M18: 0 | N18: 0 | O18: 0 | P18: 0 | Q18: 0 | R18: 0 | S18: 0 | T18: 0 | U18: 0 | V18: 0 | W18: 0 | X18: 0 | Y18: 0 | Z18: 0 | AA18: 0 | AB18: 0 | AC18: 0 | AD18: 0 | AE18: 0 | AF18: 0 | AG18: 0 | AH18: 0 | AI18: 0 | AJ18: 0 | AK18: 0 | AL18: 0 | AM18: 0 | AN18: 0 | AO18: 0 | AP18: 0 | AQ18: 0 | AR18: 0 | AS18: 0 | AT18: 0 | AU18: 0 | AV18: 0 | AW18: 0 | AX18: 0 | AY18: 0 | AZ18: 0 | BA18: 0 | BB18: 0 | BC18: 0 | BD18: 0 | BE18: 0 | BF18: 0 | BG18: 0 | BH18: 0 | BI18: 0 | BJ18: 0 | BK18: 0 | BL18: 0 | BM18: 0 | BN18: 0 | BO18: 0 | BP18: 0 | BQ18: 0 | BR18: 0 | BS18: 0 | BT18: 0 | BU18: 0 | BV18: 0 | BW18: 0 | BX18: 0 | BY18: 13.249195 | BZ18: 0 | CA18: 0 | CB18: 0 | CC18: 0 | CD18: 0 | CE18: 0 | CF18: 0 | CG18: 0 | CH18: 0 | CI18: 0 | CJ18: 0 | CK18: 0 | CL18: 0 | CM18: 0 | CN18: 0 | CO18: 13.249195 | CR18: 3.103383 | CS18: 0 | CT18: 3.103383 | CU18: 0 | CV18: 16.352578 | CW18: 0 | CX18: 0.25484312 | CY18: 0 | CZ18: 0 | DA18: 0.25484312 | DB18: 0 | DC18: 5.5343387 | DD18: 0 | DE18: 5.5343387 | DF18: 22.14176
A19: 0402 | B19: SANDÍAS | C19: 0 | D19: 0 | E19: 0 | F19: 17.980877 | G19: 0 | H19: 0 | I19: 0 | J19: 0 | K19: 0 | L19: 0 | M19: 0 | N19: 0 | O19: 0 | P19: 0 | Q19: 0 | R19: 0 | S19: 0 | T19: 0 | U19: 0 | V19: 0 | W19: 0 | X19: 0 | Y19: 0 | Z19: 0 | AA19: 0 | AB19: 0 | AC19: 0 | AD19: 0 | AE19: 0 | AF19: 0 | AG19: 0 | AH19: 0 | AI19: 0 | AJ19: 0 | AK19: 0 | AL19: 0 | AM19: 0 | AN19: 0 | AO19: 0 | AP19: 0 | AQ19: 0 | AR19: 0 | AS19: 0 | AT19: 0 | AU19: 0 | AV19: 0 | AW19: 0 | AX19: 0 | AY19: 0 | AZ19: 0 | BA19: 0 | BB19: 0 | BC19: 0 | BD19: 0 | BE19: 0 | BF19: 0 | BG19: 0 | BH19: 0 | BI19: 0 | BJ19: 0 | BK19: 0 | BL19: 0 | BM19: 0 | BN19: 0 | BO19: 0 | BP19: 0 | BQ19: 0 | BR19: 0 | BS19: 0 | BT19: 0 | BU19: 0 | BV19: 0 | BW19: 0 | BX19: 0 | BY19: 17.980877 | BZ19: 0 | CA19: 0 | CB19: 0 | CC19: 0 | CD19: 0 | CE19: 0 | CF19: 0 | CG19: 0 | CH19: 0 | CI19: 0 | CJ19: 0 | CK19: 0 | CL19: 0 | CM19: 0 | CN19: 0 | CO19: 17.980877 | CR19: 0.001351 | CS19: 0 | CT19: 0.001351 | CU19: 0 | CV19: 17.982228 | CW19: 0 | CX19: 0.00091782532 | CY19: 0 | CZ19: 0 | DA19: 0.00091782532 | DB19: 0 | DC19: 1.7546397 | DD19: 0 | DE19: 1.7546397 | DF19: 19.737785
A20: 0403 | B20: MELONES | C20: 0 | D20: 0 | E20: 0 | F20: 6.7308563 | G20: 0 | H20: 0 | I20: 0 | J20: 0 | K20: 0 | L20: 0 | M20: 0 | N20: 0 | O20: 0 | P20: 0 | Q20: 0 | R20: 0 | S20: 0 | T20: 0 | U20: 0 | V20: 0 | W20: 0 | X20: 0 | Y20: 0 | Z20: 0 | AA20: 0 | AB20: 0 | AC20: 0 | AD20: 0 | AE20: 0 | AF20: 0 | AG20: 0 | AH20: 0 | AI20: 0 | AJ20: 0 | AK20: 0 | AL20: 0 | AM20: 0 | AN20: 0 | AO20: 0 | AP20: 0 | AQ20: 0 | AR20: 0 | AS20: 0 | AT20: 0 | AU20: 0 | AV20: 0 | AW20: 0 | AX20: 0 | AY20: 0 | AZ20: 0 | BA20: 0 | BB20: 0 | BC20: 0 | BD20: 0 | BE20: 0 | BF20: 0 | BG20: 0 | BH20: 0 | BI20: 0 | BJ20: 0 | BK20: 0 | BL20: 0 | BM20: 0 | BN20: 0 | BO20: 0 | BP20: 0 | BQ20: 0 | BR20: 0 | BS20: 0 | BT20: 0 | BU20: 0 | BV20: 0 | BW20: 0 | BX20: 0 | BY20: 6.7308563 | BZ20: 0 | CA20: 0 | CB20: 0 | CC20: 0 | CD20: 0 | CE20: 0 | CF20: 0 | CG20: 0 | CH20: 0 | CI20: 0 | CJ20: 0 | CK20: 0 | CL20: 0 | CM20: 0 | CN20: 0 | CO20: 6.7308563 | CR20: 0.12885 | CS20: 0 | CT20: 0.12885 | CU20: 0 | CV20: 6.8597063 | CW20: 0 | CX20: 0.023222693 | CY20: 0 | CZ20: 0 | DA20: 0.023222693 | DB20: 0 | DC20: 2.4697007 | DD20: 0 | DE20: 2.4697007 | DF20: 9.3526297
A21: 0404 | B21: TOMATES | C21: 0 | D21: 0 | E21: 0 | F21: 19.71948 | G21: 0 | H21: 0 | I21: 0 | J21: 0 | K21: 0 | L21: 0 | M21: 0 | N21: 0 | O21: 0 | P21: 0 | Q21: 0 | R21: 0 | S21: 0 | T21: 0 | U21: 0 | V21: 0 | W21: 0 | X21: 0 | Y21: 0 | Z21: 0 | AA21: 0 | AB21: 0 | AC21: 0 | AD21: 0 | AE21: 0 | AF21: 0 | AG21: 0 | AH21: 0 | AI21: 0 | AJ21: 0 | AK21: 0 | AL21: 0 | AM21: 0 | AN21: 0 | AO21: 0 | AP21: 0 | AQ21: 0 | AR21: 0 | AS21: 0 | AT21: 0 | AU21: 0 | AV21: 0 | AW21: 0 | AX21: 0 | AY21: 0 | AZ21: 0 | BA21: 0 | BB21: 0 | BC21: 0 | BD21: 0 | BE21: 0 | BF21: 0 | BG21: 0 | BH21: 0 | BI21: 0 | BJ21: 0 | BK21: 0 | BL21: 0 | BM21: 0 | BN21: 0 | BO21: 0 | BP21: 0 | BQ21: 0 | BR21: 0 | BS21: 0 | BT21: 0 | BU21: 0 | BV21: 0 | BW21: 0 | BX21: 0 | BY21: 19.71948 | BZ21: 0 | CA21: 0 | CB21: 0 | CC21: 0 | CD21: 0 | CE21: 0 | CF21: 0 | CG21: 0 | CH21: 0 | CI21: 0 | CJ21: 0 | CK21: 0 | CL21: 0 | CM21: 0 | CN21: 0 | CO21: 19.71948 | CR21: 0.021992 | CS21: 0 | CT21: 0.021992 | CU21: 0 | CV21: 19.741472 | CW21: 0 | CX21: 0.0070776321 | CY21: 0 | CZ21: 0 | DA21: 0.0070776321 | DB21: 0 | DC21: 9.6300296 | DD21: 0 | DE21: 9.6300296 | DF21: 29.378579
A22: 0405 | B22: OTRAS HORTALIZAS | C22: 0 | D22: 0 | E22: 0 | F22: 19.729418 | G22: 0 | H22: 0 | I22: 0 | J22: 0 | K22: 0 | L22: 0 | M22: 0 | N22: 0 | O22: 0 | P22: 0 | Q22: 0 | R22: 0 | S22: 0 | T22: 0 | U22: 0 | V22: 0 | W22: 0 | X22: 0 | Y22: 0 | Z22: 0 | AA22: 0 | AB22: 0 | AC22: 0 | AD22: 0 | AE22: 0 | AF22: 0 | AG22: 0 | AH22: 0 | AI22: 0 | AJ22: 0 | AK22: 0 | AL22: 0 | AM22: 0 | AN22: 0 | AO22: 0 | AP22: 0 | AQ22: 0 | AR22: 0 | AS22: 0 | AT22: 0 | AU22: 0 | AV22: 0 | AW22: 0 | AX22: 0 | AY22: 0 | AZ22: 0 | BA22: 0 | BB22: 0 | BC22: 0 | BD22: 0 | BE22: 0 | BF22: 0 | BG22: 0 | BH22: 0 | BI22: 0 | BJ22: 0 | BK22: 0 | BL22: 0 | BM22: 0 | BN22: 0 | BO22: 0 | BP22: 0 | BQ22: 0 | BR22: 0 | BS22: 0 | BT22: 0 | BU22: 0 | BV22: 0 | BW22: 0 | BX22: 0 | BY22: 19.729418 | BZ22: 0 | CA22: 0 | CB22: 0 | CC22: 0 | CD22: 0 | CE22: 0 | CF22: 0 | CG22: 0 | CH22: 0 | CI22: 0 | CJ22: 0 | CK22: 0 | CL22: 0 | CM22: 0 | CN22: 0 | CO22: 19.729418 | CR22: 0.135081 | CS22: 0 | CT22: 0.135081 | CU22: 0 | CV22: 19.864499 | CW22: 0 | CX22: 0.0088498107 | CY22: 0 | CZ22: 0 | DA22: 0.0088498107 | DB22: 0 | DC22: 11.853839 | DD22: 0 | DE22: 11.853839 | DF22: 31.727188
A23: 0406 | B23: CEBOLLAS | C23: 0 | D23: 0 | E23: 0 | F23: 15.777541 | G23: 0 | H23: 0 | I23: 0 | J23: 0 | K23: 0 | L23: 0 | M23: 0 | N23: 0 | O23: 0 | P23: 0 | Q23: 0 | R23: 0 | S23: 0 | T23: 0 | U23: 0 | V23: 0 | W23: 0 | X23: 0 | Y23: 0 | Z23: 0 | AA23: 0 | AB23: 0 | AC23: 0 | AD23: 0 | AE23: 0 | AF23: 0 | AG23: 0 | AH23: 0 | AI23: 0 | AJ23: 0 | AK23: 0 | AL23: 0 | AM23: 0 | AN23: 0 | AO23: 0 | AP23: 0 | AQ23: 0 | AR23: 0 | AS23: 0 | AT23: 0 | AU23: 0 | AV23: 0 | AW23: 0 | AX23: 0 | AY23: 0 | AZ23: 0 | BA23: 0 | BB23: 0 | BC23: 0 | BD23: 0 | BE23: 0 | BF23: 0 | BG23: 0 | BH23: 0 | BI23: 0 | BJ23: 0 | BK23: 0 | BL23: 0 | BM23: 0 | BN23: 0 | BO23: 0 | BP23: 0 | BQ23: 0 | BR23: 0 | BS23: 0 | BT23: 0 | BU23: 0 | BV23: 0 | BW23: 0 | BX23: 0 | BY23: 15.777541 | BZ23: 0 | CA23: 0 | CB23: 0 | CC23: 0 | CD23: 0 | CE23: 0 | CF23: 0 | CG23: 0 | CH23: 0 | CI23: 0 | CJ23: 0 | CK23: 0 | CL23: 0 | CM23: 0 | CN23: 0 | CO23: 15.777541 | CR23: 5.210718 | CS23: 0 | CT23: 5.210718 | CU23: 0 | CV23: 20.988259 | CW23: 0 | CX23: 3.7626153 | CY23: 0 | CZ23: 0 | DA23: 3.7626153 | DB23: 0 | DC23: 12.44228 | DD23: 0 | DE23: 12.44228 | DF23: 37.193154
... A199: 6601 | B199: SERVICIOS DOMÉSTICOS | C199: 0 | D199: 0 | E199: 0 | F199: 0 | G199: 0 | H199: 0 | I199: 0 | J199: 0 | K199: 0 | L199: 0 | M199: 0 | N199: 0 | O199: 0 | P199: 0 | Q199: 0 | R199: 0 | S199: 0 | T199: 0 | U199: 0 | V199: 0 | W199: 0 | X199: 0 | Y199: 0 | Z199: 0 | AA199: 0 | AB199: 0 | AC199: 0 | AD199: 0 | AE199: 0 | AF199: 0 | AG199: 0 | AH199: 0 | AI199: 0 | AJ199: 0 | AK199: 0 | AL199: 0 | AM199: 0 | AN199: 0 | AO199: 0 | AP199: 0 | AQ199: 0 | AR199: 0 | AS199: 0 | AT199: 0 | AU199: 0 | AV199: 0 | AW199: 0 | AX199: 0 | AY199: 0 | AZ199: 0 | BA199: 0 | BB199: 0 | BC199: 0 | BD199: 0 | BE199: 0 | BF199: 0 | BG199: 0 | BH199: 0 | BI199: 0 | BJ199: 0 | BK199: 0 | BL199: 0 | BM199: 0 | BN199: 0 | BO199: 0 | BP199: 0 | BQ199: 0 | BR199: 0 | BS199: 0 | BT199: 0 | BU199: 0 | BV199: 0 | BW199: 0 | BX199: 0 | BY199: 0 | BZ199: 0 | CA199: 0 | CB199: 281.85404 | CC199: 281.85404 | CD199: 0 | CE199: 0 | CF199: 0 | CG199: 0 | CH199: 0 | CI199: 0 | CJ199: 0 | CK199: 0 | CL199: 0 | CM199: 0 | CN199: 0 | CO199: 281.85404 | CR199: 0 | CS199: 0 | CT199: 0 | CU199: 0 | CV199: 281.85404 | CW199: 0 | CX199: 0 | CY199: 0 | CZ199: 0 | DA199: 0 | DB199: 0 | DC199: 0 | DD199: 0 | DE199: 0 | DF199: 281.85404
A201: Ajustes: | B201: CIF/FOB sobre importaciones | BY201: 0 | CC201: 0 | CN201: 0 | CO201: 0 | CR201: -1767.4454 | CS201: 0 | CT201: -1767.4454 | CU201: 1767.4454 | CV201: 0 | CW201: 0 | CX201: 0 | CY201: 0 | CZ201: 0 | DA201: 0 | DB201: 0 | DC201: 0 | DD201: 0 | DE201: 0 | DF201: 0
A203: 6701 | B203: COMPRAS DIRECTAS EN EL EXTERIOR POR RESIDENTES (EMBAJADAS) | CR203: 0 | CS203: 160.52316 | CT203: 160.52316 | CU203: 0 | CV203: 160.52316 | CW203: 0 | CX203: 0 | CY203: 0 | CZ203: 0 | DA203: 0 | DB203: 0 | DC203: 0 | DD203: 0 | DE203: 0 | DF203: 160.52316
A204: 6702 | B204: COMPRAS DIRECTAS EN EL EXTERIOR POR RESIDENTES (VIAJES) | CR204: 0 | CS204: 593.63506 | CT204: 593.63506 | CU204: 0 | CV204: 593.63506 | CW204: 0 | CX204: 0 | CY204: 0 | CZ204: 0 | DA204: 0 | DB204: 0 | DC204: 0 | DD204: 0 | DE204: 0 | DF204: 593.63506
A205: 6703 | B205: COMPRAS DIRECTAS EN EL TERRITORIO NACIONAL POR NO RESIDENTES (EMBAJADAS) | CR205: 0 | CS205: 0 | CT205: 0 | CU205: 0 | CV205: 0 | CW205: 0 | CX205: 0 | CY205: 0 | CZ205: 0 | DA205: 0 | DB205: 0 | DC205: 0 | DD205: 0 | DE205: 0 | DF205: 0
A206: 6704 | B206: COMPRAS DIRECTAS EN EL TERRITORIO NACIONAL POR NO RESIDENTES (VIAJES) | CR206: 0 | CS206: 0 | CT206: 0 | CU206: 0 | CV206: 0 | CW206: 0 | CX206: 0 | CY206: 0 | CZ206: 0 | DA206: 0 | DB206: 0 | DC206: 0 | DD206: 0 | DE206: 0 | DF206: 0
DA207: 0
A208: P.1 | B208: PRODUCCIÓN TOTAL | C208: 17.964551 | D208: 113.34635 | E208: 148.0428 | F208: 134.36869 | G208: 245.74711 | H208: 53.85333 | I208: 161.51688 | J208: 452.83108 | K208: 298.45696 | L208: 561.74694 | M208: 9.9492135 | N208: 57.637825 | O208: 144.52564 | P208: 333.55313 | Q208: 178.23998 | R208: 3765.6892 | S208: 2112.4022 | T208: 306.0242 | U208: 55.774532 | V208: 161.19207 | W208: 506.84466 | X208: 675.27404 | Y208: 842.12682 | Z208: 462.49725 | AA208: 99.379698 | AB208: 18.652867 | AC208: 164.8699 | AD208: 83.780774 | AE208: 168.68092 | AF208: 437.17476 | AG208: 61.952808 | AH208: 85.472767 | AI208: 575.95736 | AJ208: 697.90459 | AK208: 105.3197 | AL208: 204.59169 | AM208: 368.42473 | AN208: 343.6521 | AO208: 1966.2169 | AP208: 234.7848 | AQ208: 60.552538 | AR208: 15102.589 | AS208: 2865.9057 | AT208: 6361.7371 | AU208: 7345.9146 | AV208: 775.70102 | AW208: 2681.095 | AX208: 45.230487 | AY208: 1561.1898 | AZ208: 171.73666 | BA208: 4036.744 | BB208: 746.25957 | BC208: 177.11201 | BD208: 1357.0263 | BE208: 155.17842 | BF208: 463.56077 | BG208: 1708.9412 | BH208: 646.67599 | BI208: 2052.764 | BJ208: 4517.9092 | BK208: 968.34355 | BL208: 577.24176 | BM208: 544.71535 | BN208: 1077.4586 | BO208: 849.08569 | BP208: 658.42439 | BQ208: 284.39982 | BR208: 686.96368 | BS208: 440.70991 | BT208: 2043.0139 | BU208: 841.48342 | BV208: 1261.8281 | BW208: 490.82039 | BX208: 526.30255 | BY208: 81501.036 | BZ208: 1105.8098 | CA208: 5670.8244 | CB208: 281.85404 | CC208: 7058.4883 | CD208: 57.723125 | CE208: 12.024793 | CF208: 26.291951 | CG208: 4153.5274 | CH208: 1025.1419 | CI208: 233.78517 | CJ208: 1430.1813 | CK208: 2233.6247 | CL208: 9.4001138 | CM208: 93.4599 | CN208: 9275.1604 | CO208: 97834.685 | CR208: 20841.37 | CS208: 4541.7156 | CT208: 25383.085 | CU208: 0 | CV208: 123217.77 | CW208: 1146.2574 | CX208: 378.00203 | CY208: 0 | CZ208: 813.43841 | DA208: 2337.6978 | DB208: -310.27375 | DC208: 9.5268238e-13 | DD208: 0 | DE208: 9.5268238e-13 | DF208: 125245.19
A210: Nota: Por razones de redondeo algunas cifras pueden presentar leves diferencias.

Sheet Utilización
A1: SISTEMA DE CUENTAS NACIONALES DE PANAMÁ
A2: CUADRO DE OFERTA Y UTILIZACIÓN
A3: UTILIZACIÓN DE PRODUCTOS A PRECIOS DE COMPRADOR
A4: AÑO: | B4: 2021
A5: (en millones de B/.)
A7: Serie Preliminar
A8: NOMENCLATURA DE PRODUCTOS Y TRANSACCIONES | C8: P. 2 C O N S U M O I N T E R M E D I O D E L A S I N D U S T R I A S (CLASIFICACIÓN DE ACTIVIDADES ECONÓMICAS - CAP) | CQ8: P.6 EXPORTACIONES FOB | CT8: P.3 GASTO DE CONSUMO FINAL | DB8: P.5 FORMACIÓN BRUTA DE CAPITAL | DG8: TOTAL UTILIZACION (1) (a precios de comprador) (Consumo intermedio productos por suma de actividades)
C9: DE MERCADO | BZ9: PARA USO FINAL PROPIO | CD9: OTRA NO DE MERCADO
B10: INDUSTRIAS | C10: 01.1 | D10: 02.1 | E10: 03.1 | F10: 04.1 | G10: 05.1 | H10: 06.1 | I10: 07.1 | J10: 08.1 | K10: 08.2 | L10: 08.3 | M10: 08.4 | N10: 09.1 | O10: 10.1 | P10: 11.1 | Q10: 12.1 | R10: 13.1 | S10: 14.1 | T10: 15.1 | U10: 16.1 | V10: 17.1 | W10: 18.1 | X10: 19.1 | Y10: 19.2 | Z10: 20.1 | AA10: 21.1 | AB10: 22.1 | AC10: 23.1 | AD10: 24.1 | AE10: 25.1 | AF10: 26.1 | AG10: 27.1 | AH10: 28.1 | AI10: 29.1 | AJ10: 30.1 | AK10: 31.1 | AL10: 31.2 | AM10: 32.1 | AN10: 33.1 | AO10: 34.1 | AP10: 35.1 | AQ10: 35.2 M | AR10: 36.1 M | AS10: 37.1 | AT10: 38.1 | AU10: 38.2 | AV10: 38.3 | AW10: 39.1 | AX10: 39.2 | AY10: 39.3 | AZ10: 39.4 | BA10: 39.5 | BB10: 39.6 | BC10: 39.7 | BD10: 39.8 | BE10: 39.9 | BF10: 40.1 | BG10: 40.2 | BH10: 41.1 M | BI10: 41.2 | BJ10: 42.1 | BK10: 42.2 | BL10: 42.3 | BM10: 43.1 M | BN10: 43.2 | BO10: 44.1 | BP10: 44.2 | BQ10: 44.3 M | BR10: 44.4 | BS10: 44.5 | BT10: 44.6 M | BU10: 45.1 M | BV10: 46.1 M | BW10: 47.1 M | BX10: 48.1 M | BZ10: 36.1 UFP | CA10: 43.1 UFP | CB10: 49.1 | CD10: 35.2 NM | CE10: 41.1 NM | CF10: 44.3 NM | CG10: 50.1 | CH10: 50.2 | CI10: 50.3 | CJ10: 45.1 NM | CK10: 46.1 NM | CL10: 47.1 NM | CM10: 48.1 NM | CT10: P31 HOGARES | CU10: P.3 ISFLSH | CX10: P.3 GOBIERNO GENERAL
A11: CÓDIGO | B11: P R O D U C T O S | C11: Cultivo de cereales, legumbres y semillas oleaginosas | D11: Cultivo de maiz | E11: Cultivo de arroz | F11: Cultivo de vegetales, raíces y tubérculos | G11: Cultivo de Banano | H11: Cultivo de otras frutas y nueces | I11: Otras actividades agrícolas | J11: Cría de ganado bovino (excluye búfalo) | K11: Cría de ganado porcino | L11: Cría de aves de corral | M11: Cría de otros animales y obtención de subproductos | N11: Actividades de apoyo agropecuario | O11: Silvicultura, extracción de madera y actividades conexas | P11: Pesca | Q11: Acuicultura | R11: Explotación minas y canteras | S11: Procesamiento y conservación de carne | T11: Procesamiento y conservación de pescado, crustáceos y moluscos | U11: Procesamiento y conservación de frutas y vegetales | V11: Elaboración de aceites y grasas de origen vegetal y animal | W11: Elaboración de productos lácteos | X11: Elaboración de productos de molinería, almidones y productos derivados del almidón | Y11: Elaboración de otros productos alimenticios | Z11: Elaboración de bebidas y tabaco | AA11: Fabricación de productos textiles y prendas de vestir | AB11: Fabricación de cuero, productos conexos y calzado | AC11: Producción de madera y fabricación de productos de madera y corcho, excepto muebles; fabricación de artículos de paja y de materiales trenzables | AD11: Fabricacion de papel y productos de papel | AE11: Actividades de impresión y servicios conexos | AF11: Fabricación de sustancias y productos químicos | AG11: Fabricación de productos farmacéuticos, sustancias químicas medicinales y de productos botánicos | AH11: Fabricación de productos de caucho y plástico | AI11: Fabricación de cemento, cal y yeso | AJ11: Fabricación de otros productos minerales no metálicos | AK11: Fabricación de metales comunes | AL11: Fabricación de productos metalicos elaborados, excepto maquinaria y equipo | AM11: Otras industrias manufactureras | AN11: Reparación, mantenimiento e instalación de maquinaria y equipo comercial e industrial | AO11: Suministro de electricidad, gas, vapor y aire acondicionado | AP11: Captación, tratamiento y distribuciòn de agua | AQ11: Recogida, tratamiento y eliminación de desechos, recuperación de materiales y actividades de descontaminación y otros servicios de eliminación de desechos | AR11: Construcción | AS11: Comercio al por mayor y menor en zona franca | AT11: Comercio al por mayor, en comisión y de vehículos automotores | AU11: Comercio al por menor | AV11: Mantenimiento y reparación de vehículos automotores y bicicletas | AW11: Transporte por vía terrestre; transporte por tuberías | AX11: Transporte por vía acuática | AY11: Transporte por vía aérea | AZ11: Servicio de almacenamiento y depósito | BA11: Actividades de servicio vinculadas al transporte por vía acuática: Autoridad del Canal de Panamá (ACP) | BB11: Otras actividades de servicio vinculado al transporte por vía acuática | BC11: Actividades de servicio vinculado al transporte por vía aérea: aeropuertos | BD11: Otros actividades de apoyo al transporte | BE11: Actividades postales y de mensajería | BF11: Actividades de alojamientos | BG11: Actividades de servicios de comidas y bebidas | BH11: Actividades de información y comunicación excluída telecomunicaciones | BI11: Telecomunicaciones | BJ11: Actividades de servicios financieros, excepto seguros y fondos de pensiones | BK11: Actividades de seguros, reaseguros y fondos de pensiones, excepto los planes de seguridad social de afiliación obligatoria | BL11: Actividades auxiliares de las actividades de servicios financieros | BM11: Alquiler de viviendas | BN11: Alquileres no residenciales y otras actividades inmobiliarias | BO11: Actividades jurídicas y de contabilidad | BP11: Actividades de arquitectura e ingeniería, ensayos y análisis técnicos | BQ11: Investigación científicas y desarrollo | BR11: Publicidad y estudios de mercados | BS11: Otras actividades profesionales, científicas y técnicas | BT11: Actividades de servicio administrativo y de apoyo | BU11: Enseñanza | BV11: Actividades de atención de la salud humana y de asistencia social | BW11: Actividades artísticas, de entretenimiento y recreativas | BX11: Otras actividades de servicio | BY11: SUBTOTAL DE MERCADO | BZ11: Construcción | CA11: Alquiler de viviendas | CB11: Actividades de los hogares como empleadores de personal doméstico | CC11: SUBTOTAL PARA USO FINAL PROPIO | CD11: Recogida, tratamiento y eliminación de desechos, recuperación de materiales y actividades de descontaminación y otros servicios de eliminación de desechos | CE11: Actividades de información y comunicación excluída telecomunicaciones | CF11: Investigación científicas y desarrollo | CG11: Administración pública y defensa; exceptos planes de seguridad social de afiliación obligatoria | CH11: Prestación de servicios a la comunidad en general | CI11: Actividades de planes de seguridad social de afiliación obligatoria | CJ11: Enseñanza | CK11: Actividades de atención de la salud humana y de asistencia social | CL11: Actividades artísticas, de entretenimiento y recreativas | CM11: Otras actividades de servicio | CN11: SUBTOTAL OTRA DE NO DE MERCADO | CO11: P.2 TOTAL CONSUMO INTERMEDIO | CQ11: P.61 BIENES | CR11: P.62 SERVICIOS | CS11: P.6 TOTAL | CU11: P.31 INDIVIDUAL | CV11: P.32 COLECTIVO | CW11: SUBTOTAL ISFLSH | CX11: P.31 INDIVIDUAL | CY11: P.32 COLECTIVO | CZ11: SUBTOTAL GOBIERNO GENERAL | DA11: P.3 TOTAL GASTO DE CONSUMO FINAL | DB11: P.51 FORMACION BRUTA DE CAPITAL | DC11: P.52 VARIACION DE EXISTENCIAS | DD11: OTRAS VARIACIONES DE EXISTENCIA | DE11: P.53 AQUISICIONES MENOS DISPOSICIONES DE OBJETOS VALIOSOS | DF11: P.5 TOTAL FORMACION BRUTA DE CAPITAL
A12: 0101 | B12: TRIGO | C12: 0 | D12: 0 | E12: 0 | F12: 0 | G12: 0 | H12: 0 | I12: 0 | J12: 0 | K12: 0 | L12: 0 | M12: 0 | N12: 0 | O12: 0 | P12: 0 | Q12: 0 | R12: 0 | S12: 0.86516582 | T12: 0 | U12: 0 | V12: 0 | W12: 0 | X12: 46.297446 | Y12: 3.3700846 | Z12: 0 | AA12: 0 | AB12: 0 | AC12: 0 | AD12: 0 | AE12: 0 | AF12: 0 | AG12: 0 | AH12: 0 | AI12: 0 | AJ12: 0 | AK12: 0 | AL12: 0 | AM12: 0 | AN12: 0 | AO12: 0 | AP12: 0 | AQ12: 0 | AR12: =+[1]Utilización!AR12+[1]Utilización!AS12+[1]Utilización!AT12 -> 0 | AS12: 0 | AT12: 0 | AU12: 0 | AV12: 0 | AW12: 0 | AX12: 0 | AY12: 0 | AZ12: 0 | BA12: 0 | BB12: 0 | BC12: 0 | BD12: 0 | BE12: 0 | BF12: 0 | BG12: 0 | BH12: 0 | BI12: 0 | BJ12: 0 | BK12: 0 | BL12: 0 | BM12: 0 | BN12: 0 | BO12: 0 | BP12: 0 | BQ12: 0 | BR12: 0 | BS12: 0 | BT12: 0 | BU12: 0 | BV12: 0 | BW12: 0 | BX12: 0 | BY12: 50.532696 | BZ12: 0 | CA12: 0 | CB12: 0 | CC12: 0 | CD12: 0 | CE12: 0 | CF12: 0 | CG12: 0 | CH12: 0 | CI12: 0 | CJ12: 0 | CK12: 0 | CL12: 0 | CM12: 0 | CN12: 0 | CO12: 50.532696 | CQ12: 0 | CR12: 0 | CS12: 0 | CT12: 0 | CU12: 0 | CV12: 0 | CW12: 0 | CX12: 0 | CY12: 0 | CZ12: 0 | DA12: 0 | DB12: 0 | DC12: 0 | DD12: 0 | DE12: 0 | DF12: 0 | DG12: 50.532696
A13: 0102 | B13: OTROS CEREALES (EXCL. MAÍZ Y ARROZ) | C13: 0.044726108 | D13: 0 | E13: 0 | F13: 0 | G13: 0 | H13: 0 | I13: 0 | J13: 0 | K13: 0 | L13: 0 | M13: 0 | N13: 0 | O13: 0 | P13: 0 | Q13: 0 | R13: 0 | S13: 2.278085 | T13: 0 | U13: 0 | V13: 0 | W13: 0 | X13: 0 | Y13: 0.91118021 | Z13: 0 | AA13: 0 | AB13: 0 | AC13: 0 | AD13: 0 | AE13: 0 | AF13: 0 | AG13: 0 | AH13: 0 | AI13: 0 | AJ13: 0 | AK13: 0 | AL13: 0 | AM13: 0 | AN13: 0 | AO13: 0 | AP13: 0 | AQ13: 0 | AR13: =+[1]Utilización!AR13+[1]Utilización!AS13+[1]Utilización!AT13 -> 0 | AS13: 0 | AT13: 0 | AU13: 0 | AV13: 0 | AW13: 0 | AX13: 0 | AY13: 0 | AZ13: 0 | BA13: 0 | BB13: 0 | BC13: 0 | BD13: 0 | BE13: 0 | BF13: 0 | BG13: 0 | BH13: 0 | BI13: 0 | BJ13: 0 | BK13: 0 | BL13: 0 | BM13: 0 | BN13: 0 | BO13: 0 | BP13: 0 | BQ13: 0 | BR13: 0 | BS13: 0 | BT13: 0 | BU13: 0 | BV13: 0 | BW13: 0 | BX13: 0 | BY13: 3.2339913 | BZ13: 0 | CA13: 0 | CB13: 0 | CC13: 0 | CD13: 0 | CE13: 0 | CF13: 0 | CG13: 0 | CH13: 0 | CI13: 0 | CJ13: 0 | CK13: 0 | CL13: 0 | CM13: 0 | CN13: 0 | CO13: 3.2339913 | CQ13: 0.01674 | CR13: 0 | CS13: 0.01674 | CT13: 0 | CU13: 0 | CV13: 0 | CW13: 0 | CX13: 0 | CY13: 0 | CZ13: 0 | DA13: 0 | DB13: 0 | DC13: 0.0019254 | DD13: 0 | DE13: 0 | DF13: 0.0019254 | DG13: 3.2526567
A14: 0103 | B14: LEGUMBRES | C14: 0.64550962 | D14: 0 | E14: 0 | F14: 0 | G14: 0 | H14: 0 | I14: 0 | J14: 0 | K14: 0 | L14: 0 | M14: 0 | N14: 0 | O14: 0 | P14: 0 | Q14: 0 | R14: 1.0182737 | S14: 2.0750072e-06 | T14: 0 | U14: 0.040887372 | V14: 0.015793767 | W14: 0.088580097 | X14: 0.17244858 | Y14: 0.569251 | Z14: 0 | AA14: 0 | AB14: 0 | AC14: 0 | AD14: 0 | AE14: 0 | AF14: 0 | AG14: 0 | AH14: 0 | AI14: 0 | AJ14: 0 | AK14: 0 | AL14: 0 | AM14: 0 | AN14: 0 | AO14: 0 | AP14: 0 | AQ14: 0 | AR14: =+[1]Utilización!AR14+[1]Utilización!AS14+[1]Utilización!AT14 -> 0 | AS14: 0 | AT14: 0 | AU14: 0 | AV14: 0 | AW14: 0 | AX14: 0 | AY14: 0 | AZ14: 0 | BA14: 0 | BB14: 0 | BC14: 0 | BD14: 0 | BE14: 0 | BF14: 0.53802171 | BG14: 14.524697 | BH14: 0 | BI14: 0 | BJ14: 0 | BK14: 0 | BL14: 0 | BM14: 0 | BN14: 0.074892234 | BO14: 0 | BP14: 0 | BQ14: 0 | BR14: 0 | BS14: 0 | BT14: 3.7474263e-05 | BU14: 0.0019133469 | BV14: 0.1845136 | BW14: 0 | BX14: 0 | BY14: 17.874822 | BZ14: 0 | CA14: 0 | CB14: 0 | CC14: 0 | CD14: 0 | CE14: 0 | CF14: 0 | CG14: 0 | CH14: 0 | CI14: 0.0026369818 | CJ14: 0 | CK14: 0.045872407 | CL14: 0 | CM14: 0 | CN14: 0.048509389 | CO14: 17.923331 | CQ14: 0.368739 | CR14: 0 | CS14: 0.368739 | CT14: 38.545961 | CU14: 0 | CV14: 0 | CW14: 0 | CX14: 0 | CY14: 0 | CZ14: 0 | DA14: 38.545961 | DB14: 0 | DC14: 2.6777357 | DD14: 0 | DE14: 0 | DF14: 2.6777357 | DG14: 59.515767
A15: 0104 | B15: SEMILLAS OLEAGINOSAS | C15: 0 | D15: 0 | E15: 0 | F15: 0 | G15: 0 | H15: 0 | I15: 0 | J15: 0 | K15: 0 | L15: 0 | M15: 0 | N15: 0 | O15: 0 | P15: 0 | Q15: 0 | R15: 0 | S15: 3.1767317 | T15: 0 | U15: 0 | V15: 13.029192 | W15: 0 | X15: 1.8487547 | Y15: 2.3888677 | Z15: 0 | AA15: 0 | AB15: 0 | AC15: 0 | AD15: 0 | AE15: 0 | AF15: 0 | AG15: 0 | AH15: 0 | AI15: 0 | AJ15: 0 | AK15: 0 | AL15: 0 | AM15: 0 | AN15: 0 | AO15: 0 | AP15: 0 | AQ15: 0 | AR15: =+[1]Utilización!AR15+[1]Utilización!AS15+[1]Utilización!AT15 -> 0 | AS15: 0 | AT15: 0 | AU15: 0 | AV15: 0 | AW15: 0 | AX15: 0 | AY15: 0 | AZ15: 0 | BA15: 0 | BB15: 0 | BC15: 0 | BD15: 0 | BE15: 0 | BF15: 0 | BG15: 0 | BH15: 0 | BI15: 0 | BJ15: 0 | BK15: 0 | BL15: 0 | BM15: 0 | BN15: 0 | BO15: 0 | BP15: 0 | BQ15: 0 | BR15: 0 | BS15: 0 | BT15: 0 | BU15: 0 | BV15: 0 | BW15: 0 | BX15: 0 | BY15: 20.443546 | BZ15: 0 | CA15: 0 | CB15: 0 | CC15: 0 | CD15: 0 | CE15: 0 | CF15: 0 | CG15: 0 | CH15: 0 | CI15: 0 | CJ15: 0 | CK15: 0 | CL15: 0 | CM15: 0 | CN15: 0 | CO15: 20.443546 | CQ15: 3.091647 | CR15: 0 | CS15: 3.091647 | CT15: 1.0277989 | CU15: 0 | CV15: 0 | CW15: 0 | CX15: 0 | CY15: 0 | CZ15: 0 | DA15: 1.0277989 | DB15: 0 | DC15: -0.00076745935 | DD15: 0 | DE15: 0 | DF15: -0.00076745935 | DG15: 24.562225
A16: 0201 | B16: MAÍZ | C16: 0 | D16: 14.033109 | E16: 0 | F16: 0 | G16: 0 | H16: 0 | I16: 0 | J16: 14.874808 | K16: 3.7849363 | L16: 28.505265 | M16: 0 | N16: 0 | O16: 0 | P16: 0 | Q16: 0 | R16: 0 | S16: 32.467805 | T16: 0 | U16: 0 | V16: 0 | W16: 0 | X16: 161.29435 | Y16: 36.393918 | Z16: 0 | AA16: 0 | AB16: 0 | AC16: 0 | AD16: 0 | AE16: 0 | AF16: 0 | AG16: 0 | AH16: 0 | AI16: 0 | AJ16: 0 | AK16: 0 | AL16: 0 | AM16: 0 | AN16: 0 | AO16: 0 | AP16: 0 | AQ16: 0 | AR16: =+[1]Utilización!AR16+[1]Utilización!AS16+[1]Utilización!AT16 -> 0 | AS16: 0 | AT16: 0 | AU16: 0 | AV16: 0 | AW16: 0 | AX16: 0 | AY16: 0 | AZ16: 0 | BA16: 0 | BB16: 0 | BC16: 0 | BD16: 0 | BE16: 0 | BF16: 0 | BG16: 0 | BH16: 0 | BI16: 0 | BJ16: 0 | BK16: 0 | BL16: 0 | BM16: 0 | BN16: 0 | BO16: 0 | BP16: 0 | BQ16: 0 | BR16: 0 | BS16: 0 | BT16: 0 | BU16: 0 | BV16: 0 | BW16: 0 | BX16: 0 | BY16: 291.35419 | BZ16: 0 | CA16: 0 | CB16: 0 | CC16: 0 | CD16: 0 | CE16: 0 | CF16: 0 | CG16: 0 | CH16: 0 | CI16: 0.00057324021 | CJ16: 0 | CK16: 0.0099719721 | CL16: 0 | CM16: 0 | CN16: 0.010545212 | CO16: 291.36473 | CQ16: 0.003999 | CR16: 0 | CS16: 0.003999 | CT16: 10.207823 | CU16: 0 | CV16: 0 | CW16: 0 | CX16: 0 | CY16: 0 | CZ16: 0 | DA16: 10.207823 | DB16: 0 | DC16: 0.020252 | DD16: 0 | DE16: 0 | DF16: 0.020252 | DG16: 301.59681
A17: 0301 | B17: ARROZ | C17: 0 | D17: 0 | E17: 6.6928735 | F17: 0 | G17: 0 | H17: 0 | I17: 0 | J17: 0 | K17: 0 | L17: 0 | M17: 0 | N17: 0 | O17: 0 | P17: 0 | Q17: 0 | R17: 0 | S17: 0 | T17: 0 | U17: 0 | V17: 0 | W17: 0 | X17: 160.00565 | Y17: 0 | Z17: 0 | AA17: 0 | AB17: 0 | AC17: 0 | AD17: 0 | AE17: 0 | AF17: 0 | AG17: 0 | AH17: 0 | AI17: 0 | AJ17: 0 | AK17: 0 | AL17: 0 | AM17: 0 | AN17: 0 | AO17: 0 | AP17: 0 | AQ17: 0 | AR17: =+[1]Utilización!AR17+[1]Utilización!AS17+[1]Utilización!AT17 -> 0 | AS17: 0 | AT17: 0 | AU17: 0 | AV17: 0 | AW17: 0 | AX17: 0 | AY17: 0 | AZ17: 0 | BA17: 0 | BB17: 0 | BC17: 0 | BD17: 0 | BE17: 0 | BF17: 0 | BG17: 0 | BH17: 0 | BI17: 0 | BJ17: 0 | BK17: 0 | BL17: 0 | BM17: 0 | BN17: 0 | BO17: 0 | BP17: 0 | BQ17: 0 | BR17: 0 | BS17: 0 | BT17: 0 | BU17: 0 | BV17: 0 | BW17: 0 | BX17: 0 | BY17: 166.69852 | BZ17: 0 | CA17: 0 | CB17: 0 | CC17: 0 | CD17: 0 | CE17: 0 | CF17: 0 | CG17: 0 | CH17: 0 | CI17: 0 | CJ17: 0 | CK17: 0 | CL17: 0 | CM17: 0 | CN17: 0 | CO17: 166.69852 | CQ17: 0 | CR17: 0 | CS17: 0 | CT17: 0 | CU17: 0 | CV17: 0 | CW17: 0 | CX17: 0 | CY17: 0 | CZ17: 0 | DA17: 0 | DB17: 0 | DC17: 0 | DD17: 0 | DE17: 0 | DF17: 0 | DG17: 166.69852
A18: 0401 | B18: HORTALIZAS DE HOJA O DE TALLO | C18: 0 | D18: 0 | E18: 0 | F18: 0.24108247 | G18: 0 | H18: 0 | I18: 0 | J18: 0 | K18: 0 | L18: 0 | M18: 0 | N18: 0 | O18: 0 | P18: 0 | Q18: 0 | R18: 0.095529988 | S18: 0 | T18: 0 | U18: 0 | V18: 0 | W18: 0 | X18: 0 | Y18: 0 | Z18: 0 | AA18: 0 | AB18: 0 | AC18: 0 | AD18: 0 | AE18: 0 | AF18: 0 | AG18: 0 | AH18: 0 | AI18: 0 | AJ18: 0 | AK18: 0 | AL18: 0 | AM18: 0 | AN18: 0 | AO18: 0 | AP18: 0 | AQ18: 0 | AR18: =+[1]Utilización!AR18+[1]Utilización!AS18+[1]Utilización!AT18 -> 0 | AS18: 0 | AT18: 0 | AU18: 0 | AV18: 0 | AW18: 0 | AX18: 0 | AY18: 0 | AZ18: 0 | BA18: 0 | BB18: 0 | BC18: 0 | BD18: 0 | BE18: 0 | BF18: 0.05592653 | BG18: 0.8939568 | BH18: 0 | BI18: 0 | BJ18: 0 | BK18: 0 | BL18: 0 | BM18: 0 | BN18: 0.0064403497 | BO18: 0 | BP18: 0 | BQ18: 0 | BR18: 0 | BS18: 0 | BT18: 3.2225953e-06 | BU18: 0.00016453807 | BV18: 0.006547243 | BW18: 0 | BX18: 0 | BY18: 1.2996511 | BZ18: 0 | CA18: 0 | CB18: 0 | CC18: 0 | CD18: 0 | CE18: 0 | CF18: 0 | CG18: 0 | CH18: 0 | CI18: 0.0011584229 | CJ18: 0 | CK18: 0.020151694 | CL18: 0 | CM18: 0 | CN18: 0.021310116 | CO18: 1.3209613 | CQ18: 0 | CR18: 0 | CS18: 0 | CT18: 20.820798 | CU18: 0 | CV18: 0 | CW18: 0 | CX18: 0 | CY18: 0 | CZ18: 0 | DA18: 20.820798 | DB18: 0 | DC18: 0 | DD18: 0 | DE18: 0 | DF18: 0 | DG18: 22.14176
A19: 0402 | B19: SANDÍAS | C19: 0 | D19: 0 | E19: 0 | F19: 1.2738669 | G19: 0 | H19: 0 | I19: 0 | J19: 0 | K19: 0 | L19: 0 | M19: 0 | N19: 0 | O19: 0 | P19: 0 | Q19: 0 | R19: 0.10457464 | S19: 0 | T19: 0 | U19: 0.0039110371 | V19: 0 | W19: 0 | X19: 0 | Y19: 0 | Z19: 0.84100698 | AA19: 0 | AB19: 0 | AC19: 0 | AD19: 0 | AE19: 0 | AF19: 0 | AG19: 0 | AH19: 0 | AI19: 0 | AJ19: 0 | AK19: 0 | AL19: 0 | AM19: 0 | AN19: 0 | AO19: 0 | AP19: 0 | AQ19: 0 | AR19: =+[1]Utilización!AR19+[1]Utilización!AS19+[1]Utilización!AT19 -> 0 | AS19: 0 | AT19: 0 | AU19: 0 | AV19: 0 | AW19: 0 | AX19: 0 | AY19: 0 | AZ19: 0 | BA19: 0 | BB19: 0 | BC19: 0 | BD19: 0 | BE19: 0 | BF19: 0.043027496 | BG19: 1.9495915 | BH19: 0 | BI19: 0 | BJ19: 0 | BK19: 0 | BL19: 0 | BM19: 0 | BN19: 0.0059893964 | BO19: 0 | BP19: 0 | BQ19: 0 | BR19: 0 | BS19: 0 | BT19: 2.9969491e-06 | BU19: 0.00015301711 | BV19: 0.006088805 | BW19: 0 | BX19: 0 | BY19: 4.2282128 | BZ19: 0 | CA19: 0 | CB19: 0 | CC19: 0 | CD19: 0 | CE19: 0 | CF19: 0 | CG19: 0 | CH19: 0 | CI19: 0.00054594306 | CJ19: 0 | CK19: 0.0094971162 | CL19: 0 | CM19: 0 | CN19: 0.010043059 | CO19: 4.2382558 | CQ19: 13.708359 | CR19: 0 | CS19: 13.708359 | CT19: 1.7911707 | CU19: 0 | CV19: 0 | CW19: 0 | CX19: 0 | CY19: 0 | CZ19: 0 | DA19: 1.7911707 | DB19: 0 | DC19: 0 | DD19: 0 | DE19: 0 | DF19: 0 | DG19: 19.737785
A20: 0403 | B20: MELONES | C20: 0 | D20: 0 | E20: 0 | F20: 0.4660249 | G20: 0 | H20: 0 | I20: 0 | J20: 0 | K20: 0 | L20: 0 | M20: 0 | N20: 0 | O20: 0 | P20: 0 | Q20: 0 | R20: 0.90949956 | S20: 0 | T20: 0 | U20: 0 | V20: 0 | W20: 0 | X20: 0 | Y20: 0 | Z20: 0 | AA20: 0 | AB20: 0 | AC20: 0 | AD20: 0 | AE20: 0 | AF20: 0 | AG20: 0 | AH20: 0 | AI20: 0 | AJ20: 0 | AK20: 0 | AL20: 0 | AM20: 0 | AN20: 0 | AO20: 0 | AP20: 0 | AQ20: 0 | AR20: =+[1]Utilización!AR20+[1]Utilización!AS20+[1]Utilización!AT20 -> 0 | AS20: 0 | AT20: 0 | AU20: 0 | AV20: 0 | AW20: 0 | AX20: 0 | AY20: 0 | AZ20: 0 | BA20: 0 | BB20: 0 | BC20: 0 | BD20: 0 | BE20: 0 | BF20: 0.31312533 | BG20: 6.05082 | BH20: 0 | BI20: 0 | BJ20: 0 | BK20: 0 | BL20: 0 | BM20: 0 | BN20: 0.043586819 | BO20: 0 | BP20: 0 | BQ20: 0 | BR20: 0 | BS20: 0 | BT20: 2.180979e-05 | BU20: 0.0011135562 | BV20: 0.044310249 | BW20: 0 | BX20: 0 | BY20: 7.8285022 | BZ20: 0 | CA20: 0 | CB20: 0 | CC20: 0 | CD20: 0 | CE20: 0 | CF20: 0 | CG20: 0 | CH20: 0 | CI20: 0.00047983277 | CJ20: 0 | CK20: 0.0083470748 | CL20: 0 | CM20: 0 | CN20: 0.0088269076 | CO20: 7.8373291 | CQ20: 0.864566 | CR20: 0 | CS20: 0.864566 | CT20: 0.65073463 | CU20: 0 | CV20: 0 | CW20: 0 | CX20: 0 | CY20: 0 | CZ20: 0 | DA20: 0.65073463 | DB20: 0 | DC20: 0 | DD20: 0 | DE20: 0 | DF20: 0 | DG20: 9.3526297
A21: 0404 | B21: TOMATES | C21: 0 | D21: 0 | E21: 0 | F21: 1.0661069 | G21: 0 | H21: 0 | I21: 0 | J21: 0 | K21: 0 | L21: 0 | M21: 0 | N21: 0 | O21: 0 | P21: 0 | Q21: 0 | R21: 0.71524114 | S21: 0 | T21: 0 | U21: 0.0040416509 | V21: 0 | W21: 0 | X21: 0 | Y21: 0 | Z21: 0 | AA21: 0 | AB21: 0 | AC21: 0 | AD21: 0 | AE21: 0 | AF21: 0 | AG21: 0 | AH21: 0 | AI21: 0 | AJ21: 0 | AK21: 0 | AL21: 0 | AM21: 0 | AN21: 0 | AO21: 0 | AP21: 0 | AQ21: 0 | AR21: =+[1]Utilización!AR21+[1]Utilización!AS21+[1]Utilización!AT21 -> 0 | AS21: 0 | AT21: 0 | AU21: 0 | AV21: 0 | AW21: 0 | AX21: 0 | AY21: 0 | AZ21: 0 | BA21: 0 | BB21: 0 | BC21: 0 | BD21: 0 | BE21: 0 | BF21: 0.32598359 | BG21: 4.3327606 | BH21: 0 | BI21: 0 | BJ21: 0 | BK21: 0 | BL21: 0 | BM21: 0 | BN21: 0.04537668 | BO21: 0 | BP21: 0 | BQ21: 0 | BR21: 0 | BS21: 0 | BT21: 2.2705394e-05 | BU21: 0.0011592835 | BV21: 0.046129817 | BW21: 0 | BX21: 0 | BY21: 6.5368224 | BZ21: 0 | CA21: 0 | CB21: 0 | CC21: 0 | CD21: 0 | CE21: 0 | CF21: 0 | CG21: 0 | CH21: 0 | CI21: 0.0076061214 | CJ21: 0 | CK21: 0.13231457 | CL21: 0 | CM21: 0 | CN21: 0.13992069 | CO21: 6.6767431 | CQ21: 0 | CR21: 0 | CS21: 0 | CT21: 22.701836 | CU21: 0 | CV21: 0 | CW21: 0 | CX21: 0 | CY21: 0 | CZ21: 0 | DA21: 22.701836 | DB21: 0 | DC21: 0 | DD21: 0 | DE21: 0 | DF21: 0 | DG21: 29.378579
A22: 0405 | B22: OTRAS HORTALIZAS | C22: 0 | D22: 0 | E22: 0 | F22: 0.28839139 | G22: 0 | H22: 0 | I22: 0 | J22: 0 | K22: 0 | L22: 0 | M22: 0 | N22: 0 | O22: 0 | P22: 0 | Q22: 0 | R22: 0.097805805 | S22: 0 | T22: 0 | U22: 0.066955262 | V22: 0 | W22: 0.24431599 | X22: 0 | Y22: 0.17949801 | Z22: 0 | AA22: 0 | AB22: 0 | AC22: 0 | AD22: 0 | AE22: 0 | AF22: 0 | AG22: 0 | AH22: 0 | AI22: 0 | AJ22: 0 | AK22: 0 | AL22: 0 | AM22: 0 | AN22: 0 | AO22: 0 | AP22: 0 | AQ22: 0 | AR22: =+[1]Utilización!AR22+[1]Utilización!AS22+[1]Utilización!AT22 -> 0 | AS22: 0 | AT22: 0 | AU22: 0 | AV22: 0 | AW22: 0 | AX22: 0 | AY22: 0 | AZ22: 0 | BA22: 0 | BB22: 0 | BC22: 0 | BD22: 0 | BE22: 0 | BF22: 0.031321126 | BG22: 0.49886198 | BH22: 0 | BI22: 0 | BJ22: 0 | BK22: 0 | BL22: 0 | BM22: 0 | BN22: 0.005476662 | BO22: 0 | BP22: 0 | BQ22: 0 | BR22: 0 | BS22: 0 | BT22: 2.7403892e-06 | BU22: 0.00013991777 | BV22: 0.0055675606 | BW22: 0 | BX22: 0 | BY22: 1.4183364 | BZ22: 0 | CA22: 0 | CB22: 0 | CC22: 0 | CD22: 0 | CE22: 0 | CF22: 0 | CG22: 0 | CH22: 0 | CI22: 0.0040474534 | CJ22: 0 | CK22: 0.070408689 | CL22: 0 | CM22: 0 | CN22: 0.074456142 | CO22: 1.4927926 | CQ22: 3.612632 | CR22: 0 | CS22: 3.612632 | CT22: 26.619159 | CU22: 0 | CV22: 0 | CW22: 0 | CX22: 0 | CY22: 0 | CZ22: 0 | DA22: 26.619159 | DB22: 0 | DC22: 0.002604676 | DD22: 0 | DE22: 0 | DF22: 0.002604676 | DG22: 31.727188
A23: 0406 | B23: CEBOLLAS | C23: 0 | D23: 0 | E23: 0 | F23: 0.66650217 | G23: 0 | H23: 0 | I23: 0 | J23: 0 | K23: 0 | L23: 0 | M23: 0 | N23: 0 | O23: 0 | P23: 0 | Q23: 0 | R23: 0.349311 | S23: 0 | T23: 0 | U23: 0 | V23: 0 | W23: 0.058516887 | X23: 0 | Y23: 0.00033015141 | Z23: 0 | AA23: 0 | AB23: 0 | AC23: 0 | AD23: 0 | AE23: 0 | AF23: 0 | AG23: 0 | AH23: 0 | AI23: 0 | AJ23: 0 | AK23: 0 | AL23: 0 | AM23: 0 | AN23: 0 | AO23: 0 | AP23: 0 | AQ23: 0 | AR23: =+[1]Utilización!AR23+[1]Utilización!AS23+[1]Utilización!AT23 -> 0 | AS23: 0 | AT23: 0 | AU23: 0 | AV23: 0 | AW23: 0 | AX23: 0 | AY23: 0 | AZ23: 0 | BA23: 0 | BB23: 0 | BC23: 0 | BD23: 0 | BE23: 0 | BF23: 0.14643678 | BG23: 0.9589828 | BH23: 0 | BI23: 0 | BJ23: 0 | BK23: 0 | BL23: 0 | BM23: 0 | BN23: 0.020383895 | BO23: 0 | BP23: 0 | BQ23: 0 | BR23: 0 | BS23: 0 | BT23: 1.0199608e-05 | BU23: 0.00052076779 | BV23: 0.020722215 | BW23: 0 | BX23: 0 | BY23: 2.2217169 | BZ23: 0 | CA23: 0 | CB23: 0 | CC23: 0 | CD23: 0 | CE23: 0 | CF23: 0 | CG23: 0 | CH23: 0 | CI23: 0.0013698692 | CJ23: 0 | CK23: 0.023829971 | CL23: 0 | CM23: 0 | CN23: 0.02519984 | CO23: 2.2469167 | CQ23: 0 | CR23: 0 | CS23: 0 | CT23: 34.946238 | CU23: 0 | CV23: 0 | CW23: 0 | CX23: 0 | CY23: 0 | CZ23: 0 | DA23: 34.946238 | DB23: 0 | DC23: 0 | DD23: 0 | DE23: 0 | DF23: 0 | DG23: 37.193154
... A199: 6601 | B199: SERVICIOS DOMÉSTICOS | C199: 0 | D199: 0 | E199: 0 | F199: 0 | G199: 0 | H199: 0 | I199: 0 | J199: 0 | K199: 0 | L199: 0 | M199: 0 | N199: 0 | O199: 0 | P199: 0 | Q199: 0 | R199: 0 | S199: 0 | T199: 0 | U199: 0 | V199: 0 | W199: 0 | X199: 0 | Y199: 0 | Z199: 0 | AA199: 0 | AB199: 0 | AC199: 0 | AD199: 0 | AE199: 0 | AF199: 0 | AG199: 0 | AH199: 0 | AI199: 0 | AJ199: 0 | AK199: 0 | AL199: 0 | AM199: 0 | AN199: 0 | AO199: 0 | AP199: 0 | AQ199: 0 | AR199: =+[1]Utilización!AR199+[1]Utilización!AS199+[1]Utilización!AT199 -> 0 | AS199: 0 | AT199: 0 | AU199: 0 | AV199: 0 | AW199: 0 | AX199: 0 | AY199: 0 | AZ199: 0 | BA199: 0 | BB199: 0 | BC199: 0 | BD199: 0 | BE199: 0 | BF199: 0 | BG199: 0 | BH199: 0 | BI199: 0 | BJ199: 0 | BK199: 0 | BL199: 0 | BM199: 0 | BN199: 0 | BO199: 0 | BP199: 0 | BQ199: 0 | BR199: 0 | BS199: 0 | BT199: 0 | BU199: 0 | BV199: 0 | BW199: 0 | BX199: 0 | BY199: 0 | BZ199: 0 | CA199: 0 | CB199: 0 | CC199: 0 | CD199: 0 | CE199: 0 | CF199: 0 | CG199: 0 | CH199: 0 | CI199: 0 | CJ199: 0 | CK199: 0 | CL199: 0 | CM199: 0 | CN199: 0 | CO199: 0 | CQ199: 0 | CR199: 0 | CS199: 0 | CT199: 281.85404 | CU199: 0 | CV199: 0 | CW199: 0 | CX199: 0 | CY199: 0 | CZ199: 0 | DA199: 281.85404 | DB199: 0 | DC199: 0 | DD199: 0 | DE199: 0 | DF199: 0 | DG199: 281.85404
CX200: 0 | CY200: 0
A201: Ajustes: | B201: CIF/FOB SOBRE IMPORTACIONES | CQ201: 0 | CR201: 0 | CS201: 0 | CT201: 0 | CU201: 0 | CV201: 0 | CW201: 0 | CX201: 0 | CY201: 0 | CZ201: 0 | DA201: 0 | DB201: 0 | DC201: 0 | DD201: 0 | DE201: 0 | DF201: 0 | DG201: 0
CO202: 0 | CX202: 0 | CY202: 0
A203: 6701 | B203: COMPRAS DIRECTAS EN EL EXTERIOR POR RESIDENTES (EMBAJADAS) | C203: 0 | D203: 0 | E203: 0 | F203: 0 | G203: 0 | H203: 0 | I203: 0 | J203: 0 | K203: 0 | L203: 0 | M203: 0 | N203: 0 | O203: 0 | P203: 0 | Q203: 0 | R203: 0 | S203: 0 | T203: 0 | U203: 0 | V203: 0 | W203: 0 | X203: 0 | Y203: 0 | Z203: 0 | AA203: 0 | AB203: 0 | AC203: 0 | AD203: 0 | AE203: 0 | AF203: 0 | AG203: 0 | AH203: 0 | AI203: 0 | AJ203: 0 | AK203: 0 | AL203: 0 | AM203: 0 | AN203: 0 | AO203: 0 | AP203: 0 | AQ203: 0 | AR203: =+[1]Utilización!AR203+[1]Utilización!AS203+[1]Utilización!AT203 -> 0 | AS203: 0 | AT203: 0 | AU203: 0 | AV203: 0 | AW203: 0 | AX203: 0 | AY203: 0 | AZ203: 0 | BA203: 0 | BB203: 0 | BC203: 0 | BD203: 0 | BE203: 0 | BF203: 0 | BG203: 0 | BH203: 0 | BI203: 0 | BJ203: 0 | BK203: 0 | BL203: 0 | BM203: 0 | BN203: 0 | BO203: 0 | BP203: 0 | BQ203: 0 | BR203: 0 | BS203: 0 | BT203: 0 | BU203: 0 | BV203: 0 | BW203: 0 | BX203: 0 | BY203: 0 | BZ203: 0 | CA203: 0 | CB203: 0 | CC203: 0 | CD203: 0 | CE203: 0 | CF203: 0 | CG203: 0 | CH203: 0 | CI203: 0 | CJ203: 0 | CK203: 0 | CL203: 0 | CM203: 0 | CN203: 0 | CO203: 0 | CQ203: 0 | CR203: 0 | CS203: 0 | CT203: 160.52316 | CU203: 0 | CV203: 0 | CW203: 0 | CX203: 0 | CY203: 0 | CZ203: 0 | DA203: 160.52316 | DB203: 0 | DC203: 0 | DD203: 0 | DE203: 0 | DF203: 0 | DG203: 160.52316
A204: 6702 | B204: COMPRAS DIRECTAS EN EL EXTERIOR POR RESIDENTES (VIAJES) | C204: 0 | D204: 0 | E204: 0 | F204: 0 | G204: 0 | H204: 0 | I204: 0 | J204: 0 | K204: 0 | L204: 0 | M204: 0 | N204: 0 | O204: 0 | P204: 0 | Q204: 0 | R204: 0 | S204: 0 | T204: 0 | U204: 0 | V204: 0 | W204: 0 | X204: 0 | Y204: 0 | Z204: 0 | AA204: 0 | AB204: 0 | AC204: 0 | AD204: 0 | AE204: 0 | AF204: 0 | AG204: 0 | AH204: 0 | AI204: 0 | AJ204: 0 | AK204: 0 | AL204: 0 | AM204: 0 | AN204: 0 | AO204: 0 | AP204: 0.027700534 | AQ204: 0 | AR204: =+[1]Utilización!AR204+[1]Utilización!AS204+[1]Utilización!AT204 -> 0 | AS204: 0 | AT204: 0 | AU204: 0 | AV204: 0 | AW204: 0 | AX204: 0 | AY204: 0 | AZ204: 0 | BA204: 0 | BB204: 0 | BC204: 0 | BD204: 0 | BE204: 0.012978892 | BF204: 0 | BG204: 0 | BH204: 0 | BI204: 0 | BJ204: 0 | BK204: 0 | BL204: 0 | BM204: 0 | BN204: 0.18484815 | BO204: 0 | BP204: 0 | BQ204: 0 | BR204: 0 | BS204: 0 | BT204: 0 | BU204: 0 | BV204: 0 | BW204: 0 | BX204: 0 | BY204: 0.22552758 | BZ204: 0.00019156723 | CA204: 0 | CB204: 0 | CC204: 0.00019156723 | CD204: 0 | CE204: 0.03375 | CF204: 0 | CG204: 10.729192 | CH204: 9.196137 | CI204: 0.012065 | CJ204: 0.00835 | CK204: 2.6994594 | CL204: 0 | CM204: 0 | CN204: 22.678953 | CO204: 22.904672 | CQ204: 0 | CR204: 0 | CS204: 0 | CT204: 570.73039 | CU204: 0 | CV204: 0 | CW204: 0 | CX204: 0 | CY204: 0 | CZ204: 0 | DA204: 570.73039 | DB204: 0 | DC204: 0 | DD204: 0 | DE204: 0 | DF204: 0 | DG204: 593.63506
A205: 6703 | B205: COMPRAS DIRECTAS EN EL TERRITORIO NACIONAL POR NO RESIDENTES (EMBAJADAS) | C205: 0 | D205: 0 | E205: 0 | F205: 0 | G205: 0 | H205: 0 | I205: 0 | J205: 0 | K205: 0 | L205: 0 | M205: 0 | N205: 0 | O205: 0 | P205: 0 | Q205: 0 | R205: 0 | S205: 0 | T205: 0 | U205: 0 | V205: 0 | W205: 0 | X205: 0 | Y205: 0 | Z205: 0 | AA205: 0 | AB205: 0 | AC205: 0 | AD205: 0 | AE205: 0 | AF205: 0 | AG205: 0 | AH205: 0 | AI205: 0 | AJ205: 0 | AK205: 0 | AL205: 0 | AM205: 0 | AN205: 0 | AO205: 0 | AP205: 0 | AQ205: 0 | AR205: =+[1]Utilización!AR205+[1]Utilización!AS205+[1]Utilización!AT205 -> 0 | AS205: 0 | AT205: 0 | AU205: 0 | AV205: 0 | AW205: 0 | AX205: 0 | AY205: 0 | AZ205: 0 | BA205: 0 | BB205: 0 | BC205: 0 | BD205: 0 | BE205: 0 | BF205: 0 | BG205: 0 | BH205: 0 | BI205: 0 | BJ205: 0 | BK205: 0 | BL205: 0 | BM205: 0 | BN205: 0 | BO205: 0 | BP205: 0 | BQ205: 0 | BR205: 0 | BS205: 0 | BT205: 0 | BU205: 0 | BV205: 0 | BW205: 0 | BX205: 0 | BY205: 0 | BZ205: 0 | CA205: 0 | CB205: 0 | CC205: 0 | CD205: 0 | CE205: 0 | CF205: 0 | CG205: 0 | CH205: 0 | CI205: 0 | CJ205: 0 | CK205: 0 | CL205: 0 | CM205: 0 | CN205: 0 | CO205: 0 | CQ205: 0 | CR205: 39.6 | CS205: 39.6 | CT205: -39.6 | CU205: 0 | CV205: 0 | CW205: 0 | CX205: 0 | CY205: 0 | CZ205: 0 | DA205: -39.6 | DB205: 0 | DC205: 0 | DD205: 0 | DE205: 0 | DF205: 0 | DG205: -1.2789769e-13
A206: 6704 | B206: COMPRAS DIRECTAS EN EL TERRITORIO NACIONAL POR NO RESIDENTES (VIAJES) | C206: 0 | D206: 0 | E206: 0 | F206: 0 | G206: 0 | H206: 0 | I206: 0 | J206: 0 | K206: 0 | L206: 0 | M206: 0 | N206: 0 | O206: 0 | P206: 0 | Q206: 0 | R206: 0 | S206: 0 | T206: 0 | U206: 0 | V206: 0 | W206: 0 | X206: 0 | Y206: 0 | Z206: 0 | AA206: 0 | AB206: 0 | AC206: 0 | AD206: 0 | AE206: 0 | AF206: 0 | AG206: 0 | AH206: 0 | AI206: 0 | AJ206: 0 | AK206: 0 | AL206: 0 | AM206: 0 | AN206: 0 | AO206: 0 | AP206: 0 | AQ206: 0 | AR206: =+[1]Utilización!AR206+[1]Utilización!AS206+[1]Utilización!AT206 -> 0 | AS206: 0 | AT206: 0 | AU206: 0 | AV206: 0 | AW206: 0 | AX206: 0 | AY206: 0 | AZ206: 0 | BA206: 0 | BB206: 0 | BC206: 0 | BD206: 0 | BE206: 0 | BF206: 0 | BG206: 0 | BH206: 0 | BI206: 0 | BJ206: 0 | BK206: 0 | BL206: 0 | BM206: 0 | BN206: 0 | BO206: 0 | BP206: 0 | BQ206: 0 | BR206: 0 | BS206: 0 | BT206: 0 | BU206: 0 | BV206: 0 | BW206: 0 | BX206: 0 | BY206: 0 | BZ206: 0 | CA206: 0 | CB206: 0 | CC206: 0 | CD206: 0 | CE206: 0 | CF206: 0 | CG206: 0 | CH206: 0 | CI206: 0 | CJ206: 0 | CK206: 0 | CL206: 0 | CM206: 0 | CN206: 0 | CO206: 0 | CQ206: 0 | CR206: 2093.5226 | CS206: 2093.5226 | CT206: -2093.5226 | CU206: 0 | CV206: 0 | CW206: 0 | CX206: 0 | CY206: 0 | CZ206: 0 | DA206: -2093.5226 | DB206: 0 | DC206: 0 | DD206: 0 | DE206: 0 | DF206: 0 | DG206: -7.2759576e-12
B208: TOTAL CONSUMO INTERMEDIO | C208: 6.5327517 | D208: 48.113667 | E208: 60.447503 | F208: 53.98736 | G208: 83.958835 | H208: 12.070018 | I208: 56.303311 | J208: 222.10841 | K208: 123.28798 | L208: 273.39708 | M208: 1.488807 | N208: 20.215764 | O208: 22.411611 | P208: 80.171294 | Q208: 57.587683 | R208: 1208.108 | S208: 1413.6148 | T208: 173.71119 | U208: 27.421135 | V208: 98.732229 | W208: 279.52173 | X208: 456.1341 | Y208: 530.40894 | Z208: 239.24244 | AA208: 60.25008 | AB208: 12.082875 | AC208: 104.53278 | AD208: 50.385547 | AE208: 94.27571 | AF208: 240.18675 | AG208: 28.764773 | AH208: 49.528033 | AI208: 326.48755 | AJ208: 354.27866 | AK208: 78.228754 | AL208: 93.930263 | AM208: 163.12506 | AN208: 154.448 | AO208: 623.46357 | AP208: 96.193498 | AQ208: 17.960618 | AR208: =+[1]Utilización!AR208+[1]Utilización!AS208+[1]Utilización!AT208 -> 5740.15 | AS208: 1032.8973 | AT208: 1889.6962 | AU208: 2207.3526 | AV208: 158.34223 | AW208: 959.89003 | AX208: 20.833651 | AY208: 1114.1006 | AZ208: 53.375226 | BA208: 214.44018 | BB208: 285.77208 | BC208: 36.967549 | BD208: 543.76393 | BE208: 69.953506 | BF208: 231.36982 | BG208: 941.48525 | BH208: 241.873 | BI208: 821.24138 | BJ208: 1115.2132 | BK208: 548.61045 | BL208: 239.5668 | BM208: 31.132859 | BN208: 366.97587 | BO208: 194.12132 | BP208: 202.58801 | BQ208: 76.508889 | BR208: 227.02712 | BS208: 145.466 | BT208: 564.57207 | BU208: 239.29378 | BV208: 449.68101 | BW208: 187.66123 | BX208: 160.86901 | BY208: 29409.891 | BZ208: 414.08566 | CA208: 582.37378 | CB208: 0 | CC208: 996.45944 | CD208: 29.003208 | CE208: 5.7357398 | CF208: 11.047699 | CG208: 1237.0118 | CH208: 215.35365 | CI208: 19.144369 | CJ208: 76.313088 | CK208: 409.00655 | CL208: 2.4623118 | CM208: 43.941605 | CN208: 2049.0201 | CO208: 32455.371 | CQ208: 15207.014 | CR208: 12501.274 | CS208: 27708.288 | CT208: 33934.696 | CU208: 115.0575 | CV208: 0 | CW208: 115.0575 | CX208: 4046.7088 | CY208: 5163.0929 | CZ208: 9209.8017 | DA208: 43259.555 | DB208: 18446.12 | DC208: 3375.8603 | DD208: 0 | DE208: 0 | DF208: 21821.981 | DG208: 125245.19
